PGPError                                  Traceback (most recent call last)
File ~/cluster-env/clonedenv/lib/python3.11/site-packages/spark_engine/common/pgp.py:134, in PGP.decrypt_file(self, input_file, output_path)
    131     enc_message = pgpy.PGPMessage.from_blob(rb_file.read())
    133 decrypted_message = (
--> 134     self.privkey.unlock(self.passphrase).__enter__().decrypt(enc_message).message
    135     if self.privkey.is_protected
    136     else self.privkey.decrypt(enc_message).message
    137 )
    139 file_name = os.path.basename(input_file).removesuffix(".pgp")

File ~/cluster-env/clonedenv/lib/python3.11/site-packages/pgpy/decorators.py:128, in KeyAction.__call__.<locals>._action(key, *args, **kwargs)
    127 with self.usage(key, kwargs.get('user', None)) as _key:
--> 128     self.check_attributes(key)
    130     # do the thing

File ~/cluster-env/clonedenv/lib/python3.11/site-packages/pgpy/decorators.py:114, in KeyAction.check_attributes(self, key)
    113 if getattr(key, attr) != expected:
--> 114     raise PGPError("Expected: {attr:s} == {eval:s}. Got: {got:s}"
    115                    "".format(attr=attr, eval=str(expected), got=str(getattr(key, attr))))

PGPError: Expected: is_unlocked == True. Got: False

During handling of the above exception, another exception occurred:

OSError                                   Traceback (most recent call last)
Cell In[55], line 56, in decrypt_files(input_folder, output_folder, pgp_enabled)
     55 try:
---> 56     pgp.decrypt_file(input_file, output_folder)
     57     logger.info(f"Decrypted {input_file} successfully")

File ~/cluster-env/clonedenv/lib/python3.11/site-packages/spark_engine/common/pgp.py:148, in PGP.decrypt_file(self, input_file, output_path)
    147 except Exception as e:
--> 148     raise IOError(f"Failed to decrypt file: {str(e)}")

OSError: Failed to decrypt file: Expected: is_unlocked == True. Got: False

During handling of the above exception, another exception occurred:

OSError                                   Traceback (most recent call last)
Cell In[58], line 6
      2 pgp_enabled = True
      4 try:
      5     # Decrypt files from encrypted to decrypted folder
----> 6     decrypt_files(
      7         input_folder=base_path,
      8         output_folder=decrypted_folder,
      9         pgp_enabled=pgp_enabled
     10     )
     11 except Exception as e:
     12     logger.error(f"Error during processing: {str(e)}")

Cell In[55], line 60, in decrypt_files(input_folder, output_folder, pgp_enabled)
     58 except Exception as e:
     59     logger.error(f"Failed to decrypt {input_file}: {str(e)}")
---> 60     raise IOError(f"Failed to decrypt {input_file}: {str(e)}")

OSError: Failed to decrypt ab08da5e-0f71-423b-a811-bd0af21f182b/f1da4f29-81af-4030-9190-889e5fa725bf/Files/user_data/pdos_webreport/encrypted/BOP PD & OS.xlsx.pgp: Failed to decrypt file: Expected: is_unlocked == True. Got: False
